Exception in thread Thread-4:
Traceback (most recent call last):
  File "/home/nuc/.local/lib/python3.8/site-packages/urllib3/connection.py", line 174, in _new_conn
    conn = connection.create_connection(
  File "/home/nuc/.local/lib/python3.8/site-packages/urllib3/util/connection.py", line 95, in create_connection
    raise err
  File "/home/nuc/.local/lib/python3.8/site-packages/urllib3/util/connection.py", line 85, in create_connection
    sock.connect(sa)
socket.timeout: timed out

During handling of the above exception, another exception occurred:

Traceback (most recent call last):
  File "/home/nuc/.local/lib/python3.8/site-packages/urllib3/connectionpool.py", line 703, in urlopen
    httplib_response = self._make_request(
  File "/home/nuc/.local/lib/python3.8/site-packages/urllib3/connectionpool.py", line 398, in _make_request
    conn.request(method, url, **httplib_request_kw)
  File "/home/nuc/.local/lib/python3.8/site-packages/urllib3/connection.py", line 239, in request
    super(HTTPConnection, self).request(method, url, body=body, headers=headers)
  File "/usr/lib/python3.8/http/client.py", line 1256, in request
    self._send_request(method, url, body, headers, encode_chunked)
  File "/usr/lib/python3.8/http/client.py", line 1302, in _send_request
    self.endheaders(body, encode_chunked=encode_chunked)
  File "/usr/lib/python3.8/http/client.py", line 1251, in endheaders
    self._send_output(message_body, encode_chunked=encode_chunked)
  File "/usr/lib/python3.8/http/client.py", line 1011, in _send_output
    self.send(msg)
  File "/usr/lib/python3.8/http/client.py", line 951, in send
    self.connect()
  File "/home/nuc/.local/lib/python3.8/site-packages/urllib3/connection.py", line 205, in connect
    conn = self._new_conn()
  File "/home/nuc/.local/lib/python3.8/site-packages/urllib3/connection.py", line 179, in _new_conn
    raise ConnectTimeoutError(
urllib3.exceptions.ConnectTimeoutError: (<urllib3.connection.HTTPConnection object at 0x7f684af7ee50>, 'Connection to 10.196.80.209 timed out. (connect timeout=30)')

During handling of the above exception, another exception occurred:

Traceback (most recent call last):
  File "/home/nuc/.local/lib/python3.8/site-packages/requests/adapters.py", line 489, in send
    resp = conn.urlopen(
  File "/home/nuc/.local/lib/python3.8/site-packages/urllib3/connectionpool.py", line 787, in urlopen
    retries = retries.increment(
  File "/home/nuc/.local/lib/python3.8/site-packages/urllib3/util/retry.py", line 592, in increment
    raise MaxRetryError(_pool, url, error or ResponseError(cause))
urllib3.exceptions.MaxRetryError: HTTPConnectionPool(host='10.196.80.209', port=80): Max retries exceeded with url: /config (Caused by ConnectTimeoutError(<urllib3.connection.HTTPConnection object at 0x7f684af7ee50>, 'Connection to 10.196.80.209 timed out. (connect timeout=30)'))

During handling of the above exception, another exception occurred:

Traceback (most recent call last):
  File "/usr/lib/python3.8/threading.py", line 932, in _bootstrap_inner
    self.run()
  File "nuc5_client.py", line 48, in run
    response = requests.post( pwr.nuc_to_plug[self.nuc], data = packet_json, timeout = 30)
  File "/home/nuc/.local/lib/python3.8/site-packages/requests/api.py", line 115, in post
    return request("post", url, data=data, json=json, **kwargs)
  File "/home/nuc/.local/lib/python3.8/site-packages/requests/api.py", line 59, in request
    return session.request(method=method, url=url, **kwargs)
  File "/home/nuc/.local/lib/python3.8/site-packages/requests/sessions.py", line 587, in request
    resp = self.send(prep, **send_kwargs)
  File "/home/nuc/.local/lib/python3.8/site-packages/requests/sessions.py", line 701, in send
    r = adapter.send(request, **kwargs)
  File "/home/nuc/.local/lib/python3.8/site-packages/requests/adapters.py", line 553, in send
    raise ConnectTimeout(e, request=request)
requests.exceptions.ConnectTimeout: HTTPConnectionPool(host='10.196.80.209', port=80): Max retries exceeded with url: /config (Caused by ConnectTimeoutError(<urllib3.connection.HTTPConnection object at 0x7f684af7ee50>, 'Connection to 10.196.80.209 timed out. (connect timeout=30)'))
Exception in thread Thread-6:
Traceback (most recent call last):
  File "/home/nuc/.local/lib/python3.8/site-packages/urllib3/connection.py", line 174, in _new_conn
    conn = connection.create_connection(
  File "/home/nuc/.local/lib/python3.8/site-packages/urllib3/util/connection.py", line 95, in create_connection
    raise err
  File "/home/nuc/.local/lib/python3.8/site-packages/urllib3/util/connection.py", line 85, in create_connection
    sock.connect(sa)
socket.timeout: timed out

During handling of the above exception, another exception occurred:

Traceback (most recent call last):
  File "/home/nuc/.local/lib/python3.8/site-packages/urllib3/connectionpool.py", line 703, in urlopen
    httplib_response = self._make_request(
  File "/home/nuc/.local/lib/python3.8/site-packages/urllib3/connectionpool.py", line 398, in _make_request
    conn.request(method, url, **httplib_request_kw)
  File "/home/nuc/.local/lib/python3.8/site-packages/urllib3/connection.py", line 239, in request
    super(HTTPConnection, self).request(method, url, body=body, headers=headers)
  File "/usr/lib/python3.8/http/client.py", line 1256, in request
    self._send_request(method, url, body, headers, encode_chunked)
  File "/usr/lib/python3.8/http/client.py", line 1302, in _send_request
    self.endheaders(body, encode_chunked=encode_chunked)
  File "/usr/lib/python3.8/http/client.py", line 1251, in endheaders
    self._send_output(message_body, encode_chunked=encode_chunked)
  File "/usr/lib/python3.8/http/client.py", line 1011, in _send_output
    self.send(msg)
  File "/usr/lib/python3.8/http/client.py", line 951, in send
    self.connect()
  File "/home/nuc/.local/lib/python3.8/site-packages/urllib3/connection.py", line 205, in connect
    conn = self._new_conn()
  File "/home/nuc/.local/lib/python3.8/site-packages/urllib3/connection.py", line 179, in _new_conn
    raise ConnectTimeoutError(
urllib3.exceptions.ConnectTimeoutError: (<urllib3.connection.HTTPConnection object at 0x7f684a6f22e0>, 'Connection to 10.196.80.209 timed out. (connect timeout=30)')

During handling of the above exception, another exception occurred:

Traceback (most recent call last):
  File "/home/nuc/.local/lib/python3.8/site-packages/requests/adapters.py", line 489, in send
    resp = conn.urlopen(
  File "/home/nuc/.local/lib/python3.8/site-packages/urllib3/connectionpool.py", line 787, in urlopen
    retries = retries.increment(
  File "/home/nuc/.local/lib/python3.8/site-packages/urllib3/util/retry.py", line 592, in increment
    raise MaxRetryError(_pool, url, error or ResponseError(cause))
urllib3.exceptions.MaxRetryError: HTTPConnectionPool(host='10.196.80.209', port=80): Max retries exceeded with url: /config (Caused by ConnectTimeoutError(<urllib3.connection.HTTPConnection object at 0x7f684a6f22e0>, 'Connection to 10.196.80.209 timed out. (connect timeout=30)'))

During handling of the above exception, another exception occurred:

Traceback (most recent call last):
  File "/usr/lib/python3.8/threading.py", line 932, in _bootstrap_inner
    self.run()
  File "nuc5_client.py", line 48, in run
    response = requests.post( pwr.nuc_to_plug[self.nuc], data = packet_json, timeout = 30)
  File "/home/nuc/.local/lib/python3.8/site-packages/requests/api.py", line 115, in post
    return request("post", url, data=data, json=json, **kwargs)
  File "/home/nuc/.local/lib/python3.8/site-packages/requests/api.py", line 59, in request
    return session.request(method=method, url=url, **kwargs)
  File "/home/nuc/.local/lib/python3.8/site-packages/requests/sessions.py", line 587, in request
    resp = self.send(prep, **send_kwargs)
  File "/home/nuc/.local/lib/python3.8/site-packages/requests/sessions.py", line 701, in send
    r = adapter.send(request, **kwargs)
  File "/home/nuc/.local/lib/python3.8/site-packages/requests/adapters.py", line 553, in send
    raise ConnectTimeout(e, request=request)
requests.exceptions.ConnectTimeout: HTTPConnectionPool(host='10.196.80.209', port=80): Max retries exceeded with url: /config (Caused by ConnectTimeoutError(<urllib3.connection.HTTPConnection object at 0x7f684a6f22e0>, 'Connection to 10.196.80.209 timed out. (connect timeout=30)'))
Exception in thread Thread-13:
Traceback (most recent call last):
  File "/home/nuc/.local/lib/python3.8/site-packages/urllib3/connection.py", line 174, in _new_conn
    conn = connection.create_connection(
  File "/home/nuc/.local/lib/python3.8/site-packages/urllib3/util/connection.py", line 95, in create_connection
    raise err
  File "/home/nuc/.local/lib/python3.8/site-packages/urllib3/util/connection.py", line 85, in create_connection
    sock.connect(sa)
socket.timeout: timed out

During handling of the above exception, another exception occurred:

Traceback (most recent call last):
  File "/home/nuc/.local/lib/python3.8/site-packages/urllib3/connectionpool.py", line 703, in urlopen
    httplib_response = self._make_request(
  File "/home/nuc/.local/lib/python3.8/site-packages/urllib3/connectionpool.py", line 398, in _make_request
    conn.request(method, url, **httplib_request_kw)
  File "/home/nuc/.local/lib/python3.8/site-packages/urllib3/connection.py", line 239, in request
    super(HTTPConnection, self).request(method, url, body=body, headers=headers)
  File "/usr/lib/python3.8/http/client.py", line 1256, in request
    self._send_request(method, url, body, headers, encode_chunked)
  File "/usr/lib/python3.8/http/client.py", line 1302, in _send_request
    self.endheaders(body, encode_chunked=encode_chunked)
  File "/usr/lib/python3.8/http/client.py", line 1251, in endheaders
    self._send_output(message_body, encode_chunked=encode_chunked)
  File "/usr/lib/python3.8/http/client.py", line 1011, in _send_output
    self.send(msg)
  File "/usr/lib/python3.8/http/client.py", line 951, in send
    self.connect()
  File "/home/nuc/.local/lib/python3.8/site-packages/urllib3/connection.py", line 205, in connect
    conn = self._new_conn()
  File "/home/nuc/.local/lib/python3.8/site-packages/urllib3/connection.py", line 179, in _new_conn
    raise ConnectTimeoutError(
urllib3.exceptions.ConnectTimeoutError: (<urllib3.connection.HTTPConnection object at 0x7f684a6fb910>, 'Connection to 10.196.80.209 timed out. (connect timeout=30)')

During handling of the above exception, another exception occurred:

Traceback (most recent call last):
  File "/home/nuc/.local/lib/python3.8/site-packages/requests/adapters.py", line 489, in send
    resp = conn.urlopen(
  File "/home/nuc/.local/lib/python3.8/site-packages/urllib3/connectionpool.py", line 787, in urlopen
    retries = retries.increment(
  File "/home/nuc/.local/lib/python3.8/site-packages/urllib3/util/retry.py", line 592, in increment
    raise MaxRetryError(_pool, url, error or ResponseError(cause))
urllib3.exceptions.MaxRetryError: HTTPConnectionPool(host='10.196.80.209', port=80): Max retries exceeded with url: /config (Caused by ConnectTimeoutError(<urllib3.connection.HTTPConnection object at 0x7f684a6fb910>, 'Connection to 10.196.80.209 timed out. (connect timeout=30)'))

During handling of the above exception, another exception occurred:

Traceback (most recent call last):
  File "/usr/lib/python3.8/threading.py", line 932, in _bootstrap_inner
    self.run()
  File "nuc5_client.py", line 48, in run
    response = requests.post( pwr.nuc_to_plug[self.nuc], data = packet_json, timeout = 30)
  File "/home/nuc/.local/lib/python3.8/site-packages/requests/api.py", line 115, in post
    return request("post", url, data=data, json=json, **kwargs)
  File "/home/nuc/.local/lib/python3.8/site-packages/requests/api.py", line 59, in request
    return session.request(method=method, url=url, **kwargs)
  File "/home/nuc/.local/lib/python3.8/site-packages/requests/sessions.py", line 587, in request
    resp = self.send(prep, **send_kwargs)
  File "/home/nuc/.local/lib/python3.8/site-packages/requests/sessions.py", line 701, in send
    r = adapter.send(request, **kwargs)
  File "/home/nuc/.local/lib/python3.8/site-packages/requests/adapters.py", line 553, in send
    raise ConnectTimeout(e, request=request)
requests.exceptions.ConnectTimeout: HTTPConnectionPool(host='10.196.80.209', port=80): Max retries exceeded with url: /config (Caused by ConnectTimeoutError(<urllib3.connection.HTTPConnection object at 0x7f684a6fb910>, 'Connection to 10.196.80.209 timed out. (connect timeout=30)'))
Exception in thread Thread-14:
Traceback (most recent call last):
  File "/home/nuc/.local/lib/python3.8/site-packages/urllib3/connection.py", line 174, in _new_conn
    conn = connection.create_connection(
  File "/home/nuc/.local/lib/python3.8/site-packages/urllib3/util/connection.py", line 95, in create_connection
    raise err
  File "/home/nuc/.local/lib/python3.8/site-packages/urllib3/util/connection.py", line 85, in create_connection
    sock.connect(sa)
socket.timeout: timed out

During handling of the above exception, another exception occurred:

Traceback (most recent call last):
  File "/home/nuc/.local/lib/python3.8/site-packages/urllib3/connectionpool.py", line 703, in urlopen
    httplib_response = self._make_request(
  File "/home/nuc/.local/lib/python3.8/site-packages/urllib3/connectionpool.py", line 398, in _make_request
    conn.request(method, url, **httplib_request_kw)
  File "/home/nuc/.local/lib/python3.8/site-packages/urllib3/connection.py", line 239, in request
    super(HTTPConnection, self).request(method, url, body=body, headers=headers)
  File "/usr/lib/python3.8/http/client.py", line 1256, in request
    self._send_request(method, url, body, headers, encode_chunked)
  File "/usr/lib/python3.8/http/client.py", line 1302, in _send_request
    self.endheaders(body, encode_chunked=encode_chunked)
  File "/usr/lib/python3.8/http/client.py", line 1251, in endheaders
    self._send_output(message_body, encode_chunked=encode_chunked)
  File "/usr/lib/python3.8/http/client.py", line 1011, in _send_output
    self.send(msg)
  File "/usr/lib/python3.8/http/client.py", line 951, in send
    self.connect()
  File "/home/nuc/.local/lib/python3.8/site-packages/urllib3/connection.py", line 205, in connect
    conn = self._new_conn()
  File "/home/nuc/.local/lib/python3.8/site-packages/urllib3/connection.py", line 179, in _new_conn
    raise ConnectTimeoutError(
urllib3.exceptions.ConnectTimeoutError: (<urllib3.connection.HTTPConnection object at 0x7f684a708520>, 'Connection to 10.196.80.209 timed out. (connect timeout=30)')

During handling of the above exception, another exception occurred:

Traceback (most recent call last):
  File "/home/nuc/.local/lib/python3.8/site-packages/requests/adapters.py", line 489, in send
    resp = conn.urlopen(
  File "/home/nuc/.local/lib/python3.8/site-packages/urllib3/connectionpool.py", line 787, in urlopen
    retries = retries.increment(
  File "/home/nuc/.local/lib/python3.8/site-packages/urllib3/util/retry.py", line 592, in increment
    raise MaxRetryError(_pool, url, error or ResponseError(cause))
urllib3.exceptions.MaxRetryError: HTTPConnectionPool(host='10.196.80.209', port=80): Max retries exceeded with url: /config (Caused by ConnectTimeoutError(<urllib3.connection.HTTPConnection object at 0x7f684a708520>, 'Connection to 10.196.80.209 timed out. (connect timeout=30)'))

During handling of the above exception, another exception occurred:

Traceback (most recent call last):
  File "/usr/lib/python3.8/threading.py", line 932, in _bootstrap_inner
    self.run()
  File "nuc5_client.py", line 48, in run
    response = requests.post( pwr.nuc_to_plug[self.nuc], data = packet_json, timeout = 30)
  File "/home/nuc/.local/lib/python3.8/site-packages/requests/api.py", line 115, in post
    return request("post", url, data=data, json=json, **kwargs)
  File "/home/nuc/.local/lib/python3.8/site-packages/requests/api.py", line 59, in request
    return session.request(method=method, url=url, **kwargs)
  File "/home/nuc/.local/lib/python3.8/site-packages/requests/sessions.py", line 587, in request
    resp = self.send(prep, **send_kwargs)
  File "/home/nuc/.local/lib/python3.8/site-packages/requests/sessions.py", line 701, in send
    r = adapter.send(request, **kwargs)
  File "/home/nuc/.local/lib/python3.8/site-packages/requests/adapters.py", line 553, in send
    raise ConnectTimeout(e, request=request)
requests.exceptions.ConnectTimeout: HTTPConnectionPool(host='10.196.80.209', port=80): Max retries exceeded with url: /config (Caused by ConnectTimeoutError(<urllib3.connection.HTTPConnection object at 0x7f684a708520>, 'Connection to 10.196.80.209 timed out. (connect timeout=30)'))
Exception in thread Thread-16:
Traceback (most recent call last):
  File "/home/nuc/.local/lib/python3.8/site-packages/urllib3/connection.py", line 174, in _new_conn
    conn = connection.create_connection(
  File "/home/nuc/.local/lib/python3.8/site-packages/urllib3/util/connection.py", line 95, in create_connection
    raise err
  File "/home/nuc/.local/lib/python3.8/site-packages/urllib3/util/connection.py", line 85, in create_connection
    sock.connect(sa)
socket.timeout: timed out

During handling of the above exception, another exception occurred:

Traceback (most recent call last):
  File "/home/nuc/.local/lib/python3.8/site-packages/urllib3/connectionpool.py", line 703, in urlopen
    httplib_response = self._make_request(
  File "/home/nuc/.local/lib/python3.8/site-packages/urllib3/connectionpool.py", line 398, in _make_request
    conn.request(method, url, **httplib_request_kw)
  File "/home/nuc/.local/lib/python3.8/site-packages/urllib3/connection.py", line 239, in request
    super(HTTPConnection, self).request(method, url, body=body, headers=headers)
  File "/usr/lib/python3.8/http/client.py", line 1256, in request
    self._send_request(method, url, body, headers, encode_chunked)
  File "/usr/lib/python3.8/http/client.py", line 1302, in _send_request
    self.endheaders(body, encode_chunked=encode_chunked)
  File "/usr/lib/python3.8/http/client.py", line 1251, in endheaders
    self._send_output(message_body, encode_chunked=encode_chunked)
  File "/usr/lib/python3.8/http/client.py", line 1011, in _send_output
    self.send(msg)
  File "/usr/lib/python3.8/http/client.py", line 951, in send
    self.connect()
  File "/home/nuc/.local/lib/python3.8/site-packages/urllib3/connection.py", line 205, in connect
    conn = self._new_conn()
  File "/home/nuc/.local/lib/python3.8/site-packages/urllib3/connection.py", line 179, in _new_conn
    raise ConnectTimeoutError(
urllib3.exceptions.ConnectTimeoutError: (<urllib3.connection.HTTPConnection object at 0x7f684a6fb5e0>, 'Connection to 10.196.80.209 timed out. (connect timeout=30)')

During handling of the above exception, another exception occurred:

Traceback (most recent call last):
  File "/home/nuc/.local/lib/python3.8/site-packages/requests/adapters.py", line 489, in send
    resp = conn.urlopen(
  File "/home/nuc/.local/lib/python3.8/site-packages/urllib3/connectionpool.py", line 787, in urlopen
    retries = retries.increment(
  File "/home/nuc/.local/lib/python3.8/site-packages/urllib3/util/retry.py", line 592, in increment
    raise MaxRetryError(_pool, url, error or ResponseError(cause))
urllib3.exceptions.MaxRetryError: HTTPConnectionPool(host='10.196.80.209', port=80): Max retries exceeded with url: /config (Caused by ConnectTimeoutError(<urllib3.connection.HTTPConnection object at 0x7f684a6fb5e0>, 'Connection to 10.196.80.209 timed out. (connect timeout=30)'))

During handling of the above exception, another exception occurred:

Traceback (most recent call last):
  File "/usr/lib/python3.8/threading.py", line 932, in _bootstrap_inner
    self.run()
  File "nuc5_client.py", line 48, in run
    response = requests.post( pwr.nuc_to_plug[self.nuc], data = packet_json, timeout = 30)
  File "/home/nuc/.local/lib/python3.8/site-packages/requests/api.py", line 115, in post
    return request("post", url, data=data, json=json, **kwargs)
  File "/home/nuc/.local/lib/python3.8/site-packages/requests/api.py", line 59, in request
    return session.request(method=method, url=url, **kwargs)
  File "/home/nuc/.local/lib/python3.8/site-packages/requests/sessions.py", line 587, in request
    resp = self.send(prep, **send_kwargs)
  File "/home/nuc/.local/lib/python3.8/site-packages/requests/sessions.py", line 701, in send
    r = adapter.send(request, **kwargs)
  File "/home/nuc/.local/lib/python3.8/site-packages/requests/adapters.py", line 553, in send
    raise ConnectTimeout(e, request=request)
requests.exceptions.ConnectTimeout: HTTPConnectionPool(host='10.196.80.209', port=80): Max retries exceeded with url: /config (Caused by ConnectTimeoutError(<urllib3.connection.HTTPConnection object at 0x7f684a6fb5e0>, 'Connection to 10.196.80.209 timed out. (connect timeout=30)'))
Exception in thread Thread-17:
Traceback (most recent call last):
  File "/home/nuc/.local/lib/python3.8/site-packages/urllib3/connection.py", line 174, in _new_conn
    conn = connection.create_connection(
  File "/home/nuc/.local/lib/python3.8/site-packages/urllib3/util/connection.py", line 95, in create_connection
    raise err
  File "/home/nuc/.local/lib/python3.8/site-packages/urllib3/util/connection.py", line 85, in create_connection
    sock.connect(sa)
socket.timeout: timed out

During handling of the above exception, another exception occurred:

Traceback (most recent call last):
  File "/home/nuc/.local/lib/python3.8/site-packages/urllib3/connectionpool.py", line 703, in urlopen
    httplib_response = self._make_request(
  File "/home/nuc/.local/lib/python3.8/site-packages/urllib3/connectionpool.py", line 398, in _make_request
    conn.request(method, url, **httplib_request_kw)
  File "/home/nuc/.local/lib/python3.8/site-packages/urllib3/connection.py", line 239, in request
    super(HTTPConnection, self).request(method, url, body=body, headers=headers)
  File "/usr/lib/python3.8/http/client.py", line 1256, in request
    self._send_request(method, url, body, headers, encode_chunked)
  File "/usr/lib/python3.8/http/client.py", line 1302, in _send_request
    self.endheaders(body, encode_chunked=encode_chunked)
  File "/usr/lib/python3.8/http/client.py", line 1251, in endheaders
    self._send_output(message_body, encode_chunked=encode_chunked)
  File "/usr/lib/python3.8/http/client.py", line 1011, in _send_output
    self.send(msg)
  File "/usr/lib/python3.8/http/client.py", line 951, in send
    self.connect()
  File "/home/nuc/.local/lib/python3.8/site-packages/urllib3/connection.py", line 205, in connect
    conn = self._new_conn()
  File "/home/nuc/.local/lib/python3.8/site-packages/urllib3/connection.py", line 179, in _new_conn
    raise ConnectTimeoutError(
urllib3.exceptions.ConnectTimeoutError: (<urllib3.connection.HTTPConnection object at 0x7f684a6f22e0>, 'Connection to 10.196.80.209 timed out. (connect timeout=30)')

During handling of the above exception, another exception occurred:

Traceback (most recent call last):
  File "/home/nuc/.local/lib/python3.8/site-packages/requests/adapters.py", line 489, in send
    resp = conn.urlopen(
  File "/home/nuc/.local/lib/python3.8/site-packages/urllib3/connectionpool.py", line 787, in urlopen
    retries = retries.increment(
  File "/home/nuc/.local/lib/python3.8/site-packages/urllib3/util/retry.py", line 592, in increment
    raise MaxRetryError(_pool, url, error or ResponseError(cause))
urllib3.exceptions.MaxRetryError: HTTPConnectionPool(host='10.196.80.209', port=80): Max retries exceeded with url: /config (Caused by ConnectTimeoutError(<urllib3.connection.HTTPConnection object at 0x7f684a6f22e0>, 'Connection to 10.196.80.209 timed out. (connect timeout=30)'))

During handling of the above exception, another exception occurred:

Traceback (most recent call last):
  File "/usr/lib/python3.8/threading.py", line 932, in _bootstrap_inner
    self.run()
  File "nuc5_client.py", line 48, in run
    response = requests.post( pwr.nuc_to_plug[self.nuc], data = packet_json, timeout = 30)
  File "/home/nuc/.local/lib/python3.8/site-packages/requests/api.py", line 115, in post
    return request("post", url, data=data, json=json, **kwargs)
  File "/home/nuc/.local/lib/python3.8/site-packages/requests/api.py", line 59, in request
    return session.request(method=method, url=url, **kwargs)
  File "/home/nuc/.local/lib/python3.8/site-packages/requests/sessions.py", line 587, in request
    resp = self.send(prep, **send_kwargs)
  File "/home/nuc/.local/lib/python3.8/site-packages/requests/sessions.py", line 701, in send
    r = adapter.send(request, **kwargs)
  File "/home/nuc/.local/lib/python3.8/site-packages/requests/adapters.py", line 553, in send
    raise ConnectTimeout(e, request=request)
requests.exceptions.ConnectTimeout: HTTPConnectionPool(host='10.196.80.209', port=80): Max retries exceeded with url: /config (Caused by ConnectTimeoutError(<urllib3.connection.HTTPConnection object at 0x7f684a6f22e0>, 'Connection to 10.196.80.209 timed out. (connect timeout=30)'))
Exception in thread Thread-19:
Traceback (most recent call last):
  File "/home/nuc/.local/lib/python3.8/site-packages/urllib3/connection.py", line 174, in _new_conn
    conn = connection.create_connection(
  File "/home/nuc/.local/lib/python3.8/site-packages/urllib3/util/connection.py", line 95, in create_connection
    raise err
  File "/home/nuc/.local/lib/python3.8/site-packages/urllib3/util/connection.py", line 85, in create_connection
    sock.connect(sa)
socket.timeout: timed out

During handling of the above exception, another exception occurred:

Traceback (most recent call last):
  File "/home/nuc/.local/lib/python3.8/site-packages/urllib3/connectionpool.py", line 703, in urlopen
    httplib_response = self._make_request(
  File "/home/nuc/.local/lib/python3.8/site-packages/urllib3/connectionpool.py", line 398, in _make_request
    conn.request(method, url, **httplib_request_kw)
  File "/home/nuc/.local/lib/python3.8/site-packages/urllib3/connection.py", line 239, in request
    super(HTTPConnection, self).request(method, url, body=body, headers=headers)
  File "/usr/lib/python3.8/http/client.py", line 1256, in request
    self._send_request(method, url, body, headers, encode_chunked)
  File "/usr/lib/python3.8/http/client.py", line 1302, in _send_request
    self.endheaders(body, encode_chunked=encode_chunked)
  File "/usr/lib/python3.8/http/client.py", line 1251, in endheaders
    self._send_output(message_body, encode_chunked=encode_chunked)
  File "/usr/lib/python3.8/http/client.py", line 1011, in _send_output
    self.send(msg)
  File "/usr/lib/python3.8/http/client.py", line 951, in send
    self.connect()
  File "/home/nuc/.local/lib/python3.8/site-packages/urllib3/connection.py", line 205, in connect
    conn = self._new_conn()
  File "/home/nuc/.local/lib/python3.8/site-packages/urllib3/connection.py", line 179, in _new_conn
    raise ConnectTimeoutError(
urllib3.exceptions.ConnectTimeoutError: (<urllib3.connection.HTTPConnection object at 0x7f684af7ebb0>, 'Connection to 10.196.80.209 timed out. (connect timeout=30)')

During handling of the above exception, another exception occurred:

Traceback (most recent call last):
  File "/home/nuc/.local/lib/python3.8/site-packages/requests/adapters.py", line 489, in send
    resp = conn.urlopen(
  File "/home/nuc/.local/lib/python3.8/site-packages/urllib3/connectionpool.py", line 787, in urlopen
    retries = retries.increment(
  File "/home/nuc/.local/lib/python3.8/site-packages/urllib3/util/retry.py", line 592, in increment
    raise MaxRetryError(_pool, url, error or ResponseError(cause))
urllib3.exceptions.MaxRetryError: HTTPConnectionPool(host='10.196.80.209', port=80): Max retries exceeded with url: /config (Caused by ConnectTimeoutError(<urllib3.connection.HTTPConnection object at 0x7f684af7ebb0>, 'Connection to 10.196.80.209 timed out. (connect timeout=30)'))

During handling of the above exception, another exception occurred:

Traceback (most recent call last):
  File "/usr/lib/python3.8/threading.py", line 932, in _bootstrap_inner
    self.run()
  File "nuc5_client.py", line 48, in run
    response = requests.post( pwr.nuc_to_plug[self.nuc], data = packet_json, timeout = 30)
  File "/home/nuc/.local/lib/python3.8/site-packages/requests/api.py", line 115, in post
    return request("post", url, data=data, json=json, **kwargs)
  File "/home/nuc/.local/lib/python3.8/site-packages/requests/api.py", line 59, in request
    return session.request(method=method, url=url, **kwargs)
  File "/home/nuc/.local/lib/python3.8/site-packages/requests/sessions.py", line 587, in request
    resp = self.send(prep, **send_kwargs)
  File "/home/nuc/.local/lib/python3.8/site-packages/requests/sessions.py", line 701, in send
    r = adapter.send(request, **kwargs)
  File "/home/nuc/.local/lib/python3.8/site-packages/requests/adapters.py", line 553, in send
    raise ConnectTimeout(e, request=request)
requests.exceptions.ConnectTimeout: HTTPConnectionPool(host='10.196.80.209', port=80): Max retries exceeded with url: /config (Caused by ConnectTimeoutError(<urllib3.connection.HTTPConnection object at 0x7f684af7ebb0>, 'Connection to 10.196.80.209 timed out. (connect timeout=30)'))
